Workbook
Name _SHR1: 'Personnaliser votre facture'!$D$30
Name _SHR2: 'Personnaliser votre facture'!$G$30
Name _Tax1: Facture!#REF!
Name _Tax2: Facture!$L$62
Name _Tax3: Facture!$L$64
Name _tax4: Facture!$L$64
Name boxes: Facture!$D$62:$D$63
Name CC: 'Personnaliser votre facture'!$G$22:$G$25
Name CCT: Facture!$G$64
Name CDB: 'Personnaliser votre facture'!$E$50
Name Country: 33
Name CS: 'Personnaliser votre facture'!$E$51
Name data1: Facture!$L$21
Name data10: Facture!$E$24
Name data11: Facture!#REF!
Name data12: Facture!#REF!
Name data13: Facture!#REF!
Name data14: Facture!#REF!
Name data15: Facture!#REF!
Name data16: Facture!#REF!
Name data17: Facture!#REF!
Name data18: Facture!#REF!
Name data19: Facture!#REF!
Name data2: Facture!$M$22
Name data20: Facture!#REF!
Name data21: Facture!#REF!
Name data22: Facture!#REF!
Name data23: Facture!#REF!
Name data24: Facture!#REF!
Name data25: Facture!#REF!
Name data26: Facture!#REF!
Name data27: Facture!#REF!
Name data28: Facture!#REF!
Name data29: Facture!#REF!
Name data3: Facture!$M$23
Name data30: Facture!#REF!
Name data31: Facture!#REF!
Name data32: Facture!#REF!
Name data33: Facture!#REF!
Name data34: Facture!#REF!
Name data35: Facture!#REF!
Name data36: Facture!#REF!
Name data37: Facture!#REF!
Name data38: Facture!#REF!
Name data39: Facture!#REF!
Name data4: Facture!$M$24
Name data40: Facture!#REF!
Name data41: Facture!#REF!
Name data42: Facture!#REF!
Name data43: Facture!#REF!
Name data44: Facture!#REF!
Name data45: Facture!#REF!
Name data46: Facture!#REF!
Name data47: Facture!$D$27
Name data48: Facture!$E$27
Name data49: Facture!$L$27
Name data5: Facture!$D$21
Name data50: Facture!#REF!
Name data51: Facture!#REF!
Name data52: Facture!#REF!

Sheet AutoOpen Stub Data

Sheet Personnaliser votre facture
D4: PERSONNALISER VOTRE FACTURE
G7: Placez votre point
G8: ICI pour un conseil utile
D10: Tapez les informations sur la société...
D12: Nom | E12: GAMESTREAM ATLAS ORGANISME DE FORMATION N° D'AGREMENT : 01 069 11 | F12: Numéro de téléphone
D13: Adresse | E13: 4 RUE DU CAIRE 1001 TUNIS | F13: Numéro de télécopie
D14: Code postal | E14: TEL: 71 258108
D15: Ville | E15: FAX : 71 259346
D16: Pays
D19: Spécifiez les informations par défaut…
E21: Taux de TVA à appliquer | G21: Cartes de crédit acceptées
D22: 1 | E22: 0.1
D23: 2 | E23: 0.18
D24: 3 | E24: 0.29
F27: TIMBRE FISCAL | G27: 0.2
D30: FALSE | E30: Partage de la numérotation du | F30: Emplacement
E31: modèle de facture sur le réseau | F31: du compteur
E33: Base de données de l'Assistant Modèle | F33: =LOWER(TemplateInformation!B3) -> c:\program files\microsoft office\office\macrolib\factbd.xls
D36: Informations sur la mise en forme
E47: 33
E48: 0
E49: FALSE
E50: FALSE
E51: Facture
E52: Facture

Sheet Facture
L13: http://www.camp.it
L17: DEVIS 2024-142
C21: Nom | D21: SOCIETE CHIMIQUE ALKIMIA | K21: Date | L21: 45313
C22: Adresse | D22: 11 RUE DES LILAS 1082 TUNIS MAHRAJENE | K22: Commande N°:
C23: Code postal | E23: Ville | H23: Pays | I23: TN | K23: Responsable | L23: service achat
C24: Téléphone | D24: 36 080 100 Fax: 71 787 283 | K24: MF | L24: 001716L/A/M/000
C26: Référence | D26: Quantité | E26: Description | L26: P.U | M26: Montant
M27: =IF(D27<>"",D27*L27,"")
D29: 25 | E29: Chaussures de sécurité S3 TONIC | L29: 150 | M29: =L29*D29 -> 3750
E30: EN ISO 20345:2011
E31: 2 P40 . 4 P41 . 4 P42 . 5 P43 .2 P 44 .1 P38 .7 P46
E32: DISPONIBLE 8 CHAUSSURES DE TRES HAUTE QUALITE
E33: MARQUE GASTON MILLE SEMELLE MICHELIN:
E34: 2P40 1P41 3P42 2P43 PRIX 390DTTC
D35: 50 | E35: ACCESSOIRES POUR SOUDAGE | L35: 0.79 | M35: =L35*D35 -> 39.5
E36: VERRE BLANC POUR MASQUE DE SOUDURE:
E37: DIM: 105 X 50.
M38: =IF(D38<>"",D38*L38,"")
D39: 200 | E39: MASQUE JETABLE ANTI-POUSSIERE | L39: 3.5 | M39: =IF(D39<>"",D39*L39,"") -> 700
E40: CONFORME A LA NORME : EN 149 AVEC UNE SOUPAPE | M40: =IF(D40<>"",D40*L40,"")
E41: D'EXPIRATION UTILISABLE POUR 08 HEURES DE TRAVAIL AU MINIMUM | M41: =IF(D41<>"",D41*L41,"")
M42: =IF(D42<>"",D42*L42,"")
M43: =IF(D43<>"",D43*L43,"")
D44: 20 | E44: RUBAN DE SIGNALISATION - JAUNE - ROUGE (FLUORESCENT) MATIERE : PVC - LONGUEUR : 50 m - LARGEUR : 50 mm - EPAISSEUR : 10/100 mm - REF. 50/50 | L44: 22 | M44: =IF(D44<>"",D44*L44,"") -> 440
M45: =IF(D45<>"",D45*L45,"")
M46: =IF(D46<>"",D46*L46,"")
M47: =IF(D47<>"",D47*L47,"")
D48: 4 | E48: PAIRE DE GANTS TRICOTES SANS COUTURE FABRIQUES EN MATERIAUX SYNTHETIQUES CONFORMEMENT A LA NORME EN- 420 ET EN- 388 | L48: 8.5 | M48: =IF(D48<>"",D48*L48,"") -> 34
M49: =IF(D49<>"",D49*L49,"")
M50: =IF(D50<>"",D50*L50,"")
M51: =IF(D51<>"",D51*L51,"")
M52: =IF(D52<>"",D52*L52,"")
D53: 10 | E53: MANCHE A AIR SANS SUPPORT COMPOSE DE : - 03 ANNEAUX COULEUR ROUGE - 02 ANNEAUX COULEUR BLANC - LONGUEUR : 1,5 METRES - SE FIXE SUR UN CERCEAU DE DIAMETRE 45 CM | L53: 280 | M53: =IF(D53<>"",D53*L53,"") -> 2800
M56: =IF(D56<>"",D56*L56,"")
M57: =IF(D57<>"",D57*L57,"")
M58: =IF(D58<>"",D58*L58,"")
M59: =IF(D60<>"",D60*L59,"")
L60: Total H.T. | M60: =SUM(M27:M59) -> 7763.5
L61: TIMBRE FISCAL | M61: 1
E62: Paiement à la livraison | L62: 0.19 | M62: =M60*0.19 -> 1475.065
...

Sheet Patientez un instant...

Sheet TemplateInformation
A1: AutoTemplateWizardDONTMESSWITHIT
A2: Database Type: | B2: Excel 5.0
A3: Database Location: | B3: C:\PROGRAM FILES\MICROSOFT OFFICE\OFFICE\MACROLIB\factbd.xls
A4: Reserved
A5: Number of Tables: | B5: 1
A6: 1 | B6: Table Name: | C6: France | D6: Number of Fields: | E6: 10 | G6: -1383939328
A7: Field Name: | B7: Facture N° | C7: Date | D7: Nom | E7: Adresse | F7: Code postal | G7: Ville | H7: Pays | I7: Téléphone | J7: TOTAL | K7: Responsable
A8: Refers To: | B8: =Facture!#REF! -> #REF! | C8: =Facture!$L$21 -> 45313 | D8: =Facture!$D$21 -> SOCIETE CHIMIQUE ALKIMIA | E8: =Facture!$D$22 -> 11 RUE DES LILAS 1082 TUNIS MAHRAJENE | F8: =Facture!$D$23 -> 0 | G8: =Facture!$F$23 -> 0 | H8: =Facture!$I$23 -> TN | I8: =Facture!$D$24 -> 36 080 100 Fax: 71 787 283 | J8: =Facture!$M$63 -> 9239.565 | K8: =Facture!$L$23 -> service achat
A9: Reserved
G10: -1261995520
G14: -462007040

Sheet Macros
